<?xml version="1.0"?>
<robot xmlns:xacro="http://www.ros.org/wiki/xacro">

    <xacro:include filename="consts.xacro" /> 

    <!-- ******** world to base joint ********** -->
    <joint name="world_to_base" type="fixed">
        <parent link="base_link"/>
        <child link="world"/>
    </joint>

    <!-- *********  FR_hip joint ********* -->
    <joint name="FR_hip_joint" type="revolute">
        <origin xyz="0.005372 -0.029025 0.34267" rpy="0 0 0"/>
        <parent link="base_link"/>
        <child link="FR_hip_link"/>
        <axis xyz="1.0 -0.0 0.0"/>
        <limit upper="0.174533" lower="-0.174533" effort="100" velocity="100"/>
    </joint>
    <!-- *********  FL_hip  ********* -->
    <joint name="FL_hip_joint" type="revolute">
        <origin xyz="0.005091 -0.147198 0.340765" rpy="0 0 0"/>
        <parent link="base_link"/>
        <child link="FL_hip_link"/>
        <axis xyz="-1.0 0.0 -0.0"/>
        <limit upper="0.174533" lower="-0.174533" effort="100" velocity="100"/>
    </joint>
    <!-- *********  BR_hip  ********* -->
    <joint name="BR_hip_joint" type="revolute">
        <origin xyz="0.471531 -0.028918 0.340765" rpy="0 0 0"/>
        <parent link="base_link"/>
        <child link="BR_hip_link"/>
        <axis xyz="1.0 -0.0 -0.0"/>
        <limit upper="0.174533" lower="-0.174533" effort="100" velocity="100"/>
    </joint>
    <!-- *********  BL_hip  ********* -->
    <joint name="BL_hip_joint" type="revolute">
        <origin xyz="0.471531 -0.147198 0.340765" rpy="0 0 0"/>
        <parent link="base_link"/>
        <child link="BL_hip_link"/>
        <axis xyz="-1.0 0.0 0.0"/>
        <limit upper="0.174533" lower="-0.174533" effort="100" velocity="100"/>
    </joint>

    <!-- *********  FR_uleg joint ********* -->
    <joint name="FR_uleg_joint" type="revolute">
        <origin xyz="-0.09964 0.06636 0.0" rpy="0 0 0"/>
        <parent link="FR_hip_link"/>
        <child link="FR_uleg_link"/>
        <axis xyz="-0.0 -1.0 0.0"/>
        <limit upper="0.785398" lower="-2.356194" effort="100" velocity="100"/>
    </joint>
    <!-- *********  FL_uleg  ********* -->
    <joint name="FL_uleg_joint" type="revolute">
        <origin xyz="-0.09964 -0.06636 0.0" rpy="0 0 0"/>
        <parent link="FL_hip_link"/>
        <child link="FL_uleg_link"/>
        <axis xyz="-0.0 -1.0 -0.0"/>
        <limit upper="0.785398" lower="-2.356194" effort="100" velocity="100"/>
    </joint>
    <!-- *********  BR_uleg  ********* -->
    <joint name="BR_uleg_joint" type="revolute">
        <origin xyz="0.09964 0.06636 0.0" rpy="0 0 0"/>
        <parent link="BR_hip_link"/>
        <child link="BR_uleg_link"/>
        <axis xyz="-0.0 1.0 -0.0"/>
        <limit upper="0.785398" lower="-2.356194" effort="100" velocity="100"/>
    </joint>
    <!-- *********  BL_uleg  ********* -->
    <joint name="BL_uleg_joint" type="revolute">
        <origin xyz="0.09964 -0.06636 0.0" rpy="0 0 0"/>
        <parent link="BL_hip_link"/>
        <child link="BL_uleg_link"/>
        <axis xyz="0.0 1.0 0.0"/>
        <limit upper="0.785398" lower="-2.356194" effort="100" velocity="100"/>
    </joint>

    <!-- *********  FR_lleg  ********* -->
    <joint name="FR_lleg_joint" type="revolute">
        <origin xyz="0.140968 0.082 -0.140969" rpy="0 0 0"/>
        <parent link="FR_uleg_link"/>
        <child link="FR_lleg_link"/>
        <axis xyz="-0.0 -1.0 0.0"/>
        <limit upper="3.839724" lower="-0.698132" effort="100" velocity="100"/>
    </joint>
    <!-- *********  FL_lleg  ********* -->
    <joint name="FL_lleg_joint" type="revolute">
        <origin xyz="0.140968 -0.082 -0.140968" rpy="0 0 0"/>
        <parent link="FL_uleg_link"/>
        <child link="FL_lleg_link"/>
        <axis xyz="-0.0 -1.0 -0.0"/>
        <limit upper="3.839724" lower="-0.698132" effort="100" velocity="100"/>
    </joint>
    <!-- *********  BR_lleg  ********* -->
    <joint name="BR_lleg_joint" type="revolute">
        <origin xyz="-0.140969 0.082 -0.140968" rpy="0 0 0"/>
        <parent link="BR_uleg_link"/>
        <child link="BR_lleg_link"/>
        <axis xyz="-0.0 1.0 -0.0"/>
        <limit upper="3.839724" lower="-0.698132" effort="100" velocity="100"/>
    </joint>
    <!-- *********  BL_lleg  ********* -->
    <joint name="BL_lleg_joint" type="revolute">
        <origin xyz="-0.140969 -0.082 -0.140968" rpy="0 0 0"/>
        <parent link="BL_uleg_link"/>
        <child link="BL_lleg_link"/>
        <axis xyz="0.0 1.0 0.0"/>
        <limit upper="3.839724" lower="-0.698132" effort="100" velocity="100"/>
    </joint>
</robot>
